Workbook

Sheet TPL
A1: recordId | B1: hospId | C1: state | D1: district | E1: hosp_type | F1: hospname | G1: GPS | H1: creation_date | I1: date_submission | J1: e_primary | K1: e_secondary | L1: e_tertiary | M1: i_primary | N1: i_secondary | O1: i_tertiary | P1: b_primary | Q1: b_secondary | R1: b_tertiary | S1: s_primary | T1: s_secondary | U1: s_tertiary | V1: avg_primary | W1: avg_secondary | X1: avg_tertiary | Y1: statecode | Z1: districtcode
A2: 746 | B2: 1 | C2: Haryana | D2: Ambala | E2: CHC | F2: CHC SHAHZADPUR | G2: =VLOOKUP(F2,Hospitals!E:H,4,FALSE) -> 30.28297 , 76.71056 | H2: 45428 | I2: 45428 | J2: 45.86 | K2: 42.604 | L2: 40.909 | M2: 17.647 | N2: 13.043 | O2: 13.043 | P2: 17.647 | Q2: 13.043 | R2: 13.043 | S2: 10 | T2: 8.333 | U2: 0 | V2: =AVERAGE(J2,M2,P2,S2) -> 22.7885 | W2: =AVERAGE(K2,N2,Q2,T2) -> 19.25575 | X2: =AVERAGE(L2,O2,R2,U2) -> 16.74875 | Y2: 13 | Z2: 001
A3: 748 | B3: 1 | C3: Haryana | D3: Ambala | E3: CHC | F3: CHC SHAHZADPUR | G3: =VLOOKUP(F3,Hospitals!E:H,4,FALSE) -> 30.28297 , 76.71056 | H3: 45428 | I3: 45428 | J3: 45.86 | K3: 42.604 | L3: 40.909 | M3: 17.647 | N3: 13.043 | O3: 13.043 | P3: 17.647 | Q3: 13.043 | R3: 13.043 | S3: 10 | T3: 8.333 | U3: 0 | V3: =AVERAGE(J3,M3,P3,S3) -> 22.7885 | W3: =AVERAGE(K3,N3,Q3,T3) -> 19.25575 | X3: =AVERAGE(L3,O3,R3,U3) -> 16.74875 | Y3: 13 | Z3: 001
A4: 905 | B4: 10 | C4: Haryana | D4: Ambala | E4: PHC | F4: PHC BOH | G4: =VLOOKUP(F4,Hospitals!E:H,4,FALSE) -> 30.37369 , 77.09641 | H4: 45490 | I4: 45490 | J4: 47.134 | K4: 43.787 | L4: 42.045 | M4: 52.941 | N4: 39.13 | O4: 39.13 | P4: 52.941 | Q4: 39.13 | R4: 39.13 | S4: 0 | T4: 0 | U4: 0 | V4: =AVERAGE(J4,M4,P4,S4) -> 38.254 | W4: =AVERAGE(K4,N4,Q4,T4) -> 30.51175 | X4: =AVERAGE(L4,O4,R4,U4) -> 30.07625 | Y4: 13 | Z4: 001
A5: 484 | B5: 100 | C5: Haryana | D5: Gurugram | E5: PRIVATE | F5: Aarvy Healthcare, Sector 90 | G5: =VLOOKUP(F5,Hospitals!E:H,4,FALSE) -> 28.40287 , 76.95277 | H5: 45386 | I5: 45386 | J5: 89.172 | K5: 88.757 | L5: 88.068 | M5: 88.235 | N5: 86.957 | O5: 86.957 | P5: 88.235 | Q5: 86.957 | R5: 86.957 | S5: 80 | T5: 75 | U5: 57.143 | V5: =AVERAGE(J5,M5,P5,S5) -> 86.4105 | W5: =AVERAGE(K5,N5,Q5,T5) -> 84.41775 | X5: =AVERAGE(L5,O5,R5,U5) -> 79.78125 | Y5: 13 | Z5: 006
A6: 1118 | B6: 1000 | C6: Haryana | D6: Fatehabad | E6: PRIVATE | F6: KHANNA ENT AND DENTAL HOSPITAL | G6: =VLOOKUP(F6,Hospitals!E:H,4,FALSE) -> 29.70815 , 75.90863 | H6: 45646 | I6: 45646 | J6: 57.325 | K6: 53.254 | L6: 51.136 | M6: 47.059 | N6: 39.13 | O6: 39.13 | P6: 47.059 | Q6: 39.13 | R6: 39.13 | S6: 0 | T6: 0 | U6: 0 | V6: =AVERAGE(J6,M6,P6,S6) -> 37.86075 | W6: =AVERAGE(K6,N6,Q6,T6) -> 32.8785 | X6: =AVERAGE(L6,O6,R6,U6) -> 32.349 | Y6: 13 | Z6: 005
A7: 1119 | B7: 1000 | C7: Haryana | D7: Fatehabad | E7: PRIVATE | F7: KHANNA ENT AND DENTAL HOSPITAL | G7: =VLOOKUP(F7,Hospitals!E:H,4,FALSE) -> 29.70815 , 75.90863 | H7: 45646 | I7: - | J7: 57.325 | K7: 53.254 | L7: 51.136 | M7: 47.059 | N7: 39.13 | O7: 39.13 | P7: 47.059 | Q7: 39.13 | R7: 39.13 | S7: 0 | T7: 0 | U7: 0 | V7: =AVERAGE(J7,M7,P7,S7) -> 37.86075 | W7: =AVERAGE(K7,N7,Q7,T7) -> 32.8785 | X7: =AVERAGE(L7,O7,R7,U7) -> 32.349 | Y7: 13 | Z7: 005
A8: 1112 | B8: 1001 | C8: Haryana | D8: Fatehabad | E8: PRIVATE | F8: PARUL ENT SKIN AND LASER CENTRE | G8: =VLOOKUP(F8,Hospitals!E:H,4,FALSE) -> #N/A | H8: 45644 | I8: - | J8: 0 | K8: 0 | L8: 0 | M8: 0 | N8: 0 | O8: 0 | P8: 0 | Q8: 0 | R8: 0 | S8: 0 | T8: 0 | U8: 0 | V8: =AVERAGE(J8,M8,P8,S8) -> 0 | W8: =AVERAGE(K8,N8,Q8,T8) -> 0 | X8: =AVERAGE(L8,O8,R8,U8) -> 0 | Y8: 13 | Z8: 005
A9: 1111 | B9: 1002 | C9: Haryana | D9: Fatehabad | E9: PRIVATE | F9: JAIPUR CHILDREN HOSPITAL | G9: =VLOOKUP(F9,Hospitals!E:H,4,FALSE) -> #N/A | H9: 45644 | I9: - | J9: 0 | K9: 0 | L9: 0 | M9: 0 | N9: 0 | O9: 0 | P9: 0 | Q9: 0 | R9: 0 | S9: 0 | T9: 0 | U9: 0 | V9: =AVERAGE(J9,M9,P9,S9) -> 0 | W9: =AVERAGE(K9,N9,Q9,T9) -> 0 | X9: =AVERAGE(L9,O9,R9,U9) -> 0 | Y9: 13 | Z9: 005
A10: 1131 | B10: 1004 | C10: Haryana | D10: Panchkula | E10: UPHC | F10: UPHC Pinjore | G10: =VLOOKUP(F10,Hospitals!E:H,4,FALSE) -> 30.70689 , 76.74921 | H10: 45677 | I10: - | J10: 0 | K10: 0 | L10: 0 | M10: 82.353 | N10: 69.565 | O10: 69.565 | P10: 82.353 | Q10: 69.565 | R10: 69.565 | S10: 0 | T10: 0 | U10: 0 | V10: =AVERAGE(J10,M10,P10,S10) -> 41.1765 | W10: =AVERAGE(K10,N10,Q10,T10) -> 34.7825 | X10: =AVERAGE(L10,O10,R10,U10) -> 34.7825 | Y10: 13 | Z10: 016
A11: 1156 | B11: 1005 | C11: Haryana | D11: Hisar | E11: PRIVATE | F11: AABHARI PLASTIC SURGERY CENTRE | G11: =VLOOKUP(F11,Hospitals!E:H,4,FALSE) -> #N/A | H11: 45688 | I11: - | J11: 0 | K11: 0 | L11: 0 | M11: 0 | N11: 0 | O11: 0 | P11: 0 | Q11: 0 | R11: 0 | S11: 0 | T11: 0 | U11: 0 | V11: =AVERAGE(J11,M11,P11,S11) -> 0 | W11: =AVERAGE(K11,N11,Q11,T11) -> 0 | X11: =AVERAGE(L11,O11,R11,U11) -> 0 | Y11: 13 | Z11: 007
A12: 1162 | B12: 1007 | C12: Haryana | D12: Hisar | E12: PRIVATE | F12: SHREE BALAJI HOSPITAL | G12: =VLOOKUP(F12,Hospitals!E:H,4,FALSE) -> 30.90096 , 75.85728 | H12: 45712 | I12: - | J12: 0 | K12: 0 | L12: 0 | M12: 0 | N12: 0 | O12: 0 | P12: 0 | Q12: 0 | R12: 0 | S12: 0 | T12: 0 | U12: 0 | V12: =AVERAGE(J12,M12,P12,S12) -> 0 | W12: =AVERAGE(K12,N12,Q12,T12) -> 0 | X12: =AVERAGE(L12,O12,R12,U12) -> 0 | Y12: 13 | Z12: 007
A13: 1157 | B13: 1009 | C13: Haryana | D13: Hisar | E13: PRIVATE | F13: DR RAM NARAIAN SONI ORTHO HOSPITAL | G13: =VLOOKUP(F13,Hospitals!E:H,4,FALSE) -> #N/A | H13: 45689 | I13: - | J13: 0 | K13: 0 | L13: 0 | M13: 0 | N13: 0 | O13: 0 | P13: 0 | Q13: 0 | R13: 0 | S13: 0 | T13: 0 | U13: 0 | V13: =AVERAGE(J13,M13,P13,S13) -> 0 | W13: =AVERAGE(K13,N13,Q13,T13) -> 0 | X13: =AVERAGE(L13,O13,R13,U13) -> 0 | Y13: 13 | Z13: 007
A14: 631 | B14: 101 | C14: Haryana | D14: Gurugram | E14: PRIVATE | F14: Manipal Hospital Gurugram | G14: =VLOOKUP(F14,Hospitals!E:H,4,FALSE) -> #N/A | H14: 45449 | I14: - | J14: 0 | K14: 0 | L14: 0 | M14: 94.118 | N14: 95.652 | O14: 95.652 | P14: 94.118 | Q14: 95.652 | R14: 95.652 | S14: 0 | T14: 0 | U14: 0 | V14: =AVERAGE(J14,M14,P14,S14) -> 47.059 | W14: =AVERAGE(K14,N14,Q14,T14) -> 47.826 | X14: =AVERAGE(L14,O14,R14,U14) -> 47.826 | Y14: 13 | Z14: 006
A15: 1158 | B15: 1011 | C15: Haryana | D15: Hisar | E15: PRIVATE | F15: SAPRA MULTISPECIALITY HOSPITAL | G15: =VLOOKUP(F15,Hospitals!E:H,4,FALSE) -> #N/A | H15: 45691 | I15: - | J15: 0 | K15: 0 | L15: 0 | M15: 0 | N15: 0 | O15: 0 | P15: 0 | Q15: 0 | R15: 0 | S15: 0 | T15: 0 | U15: 0 | V15: =AVERAGE(J15,M15,P15,S15) -> 0 | W15: =AVERAGE(K15,N15,Q15,T15) -> 0 | X15: =AVERAGE(L15,O15,R15,U15) -> 0 | Y15: 13 | Z15: 007
A16: 1161 | B16: 1013 | C16: Haryana | D16: Hisar | E16: PRIVATE | F16: Malik Hospital (Uttam Nagar Hansi) | G16: =VLOOKUP(F16,Hospitals!E:H,4,FALSE) -> #N/A | H16: 45692 | I16: - | J16: 0 | K16: 0 | L16: 0 | M16: 0 | N16: 0 | O16: 0 | P16: 0 | Q16: 0 | R16: 0 | S16: 0 | T16: 0 | U16: 0 | V16: =AVERAGE(J16,M16,P16,S16) -> 0 | W16: =AVERAGE(K16,N16,Q16,T16) -> 0 | X16: =AVERAGE(L16,O16,R16,U16) -> 0 | Y16: 13 | Z16: 007
A17: 1159 | B17: 1014 | C17: Haryana | D17: Hisar | E17: PRIVATE | F17: RAVINDRA HOSPITAL AND HEART CENTRE | G17: =VLOOKUP(F17,Hospitals!E:H,4,FALSE) -> #N/A | H17: 45691 | I17: - | J17: 0 | K17: 0 | L17: 0 | M17: 0 | N17: 0 | O17: 0 | P17: 0 | Q17: 0 | R17: 0 | S17: 0 | T17: 0 | U17: 0 | V17: =AVERAGE(J17,M17,P17,S17) -> 0 | W17: =AVERAGE(K17,N17,Q17,T17) -> 0 | X17: =AVERAGE(L17,O17,R17,U17) -> 0 | Y17: 13 | Z17: 007
A18: 839 | B18: 102 | C18: Haryana | D18: Hisar | E18: CHC | F18: CHC CUM SDH BARWALA | G18: =VLOOKUP(F18,Hospitals!E:H,4,FALSE) -> 29.36013 , 75.88086 | H18: 45477 | I18: 45477 | J18: 51.592 | K18: 48.521 | L18: 47.159 | M18: 58.824 | N18: 43.478 | O18: 43.478 | P18: 58.824 | Q18: 43.478 | R18: 43.478 | S18: 10 | T18: 8.333 | U18: 0 | V18: =AVERAGE(J18,M18,P18,S18) -> 44.81 | W18: =AVERAGE(K18,N18,Q18,T18) -> 35.9525 | X18: =AVERAGE(L18,O18,R18,U18) -> 33.52875 | Y18: 13 | Z18: 007
A19: 1170 | B19: 1020 | C19: Haryana | D19: Hisar | E19: PRIVATE | F19: KHALSA HOSPITAL MANAGEMENT | G19: =VLOOKUP(F19,Hospitals!E:H,4,FALSE) -> #N/A | H19: 45763 | I19: - | J19: 0 | K19: 0 | L19: 0 | M19: 0 | N19: 0 | O19: 0 | P19: 0 | Q19: 0 | R19: 0 | S19: 0 | T19: 0 | U19: 0 | V19: =AVERAGE(J19,M19,P19,S19) -> 0 | W19: =AVERAGE(K19,N19,Q19,T19) -> 0 | X19: =AVERAGE(L19,O19,R19,U19) -> 0 | Y19: 13 | Z19: 007
A20: 1164 | B20: 1022 | C20: Haryana | D20: Hisar | E20: PRIVATE | F20: SADBHAVNA HOSPITAL Uklana Mandi | G20: =VLOOKUP(F20,Hospitals!E:H,4,FALSE) -> #N/A | H20: 45720 | I20: - | J20: 0 | K20: 0 | L20: 0 | M20: 0 | N20: 0 | O20: 0 | P20: 0 | Q20: 0 | R20: 0 | S20: 0 | T20: 0 | U20: 0 | V20: =AVERAGE(J20,M20,P20,S20) -> 0 | W20: =AVERAGE(K20,N20,Q20,T20) -> 0 | X20: =AVERAGE(L20,O20,R20,U20) -> 0 | Y20: 13 | Z20: 007
A21: 868 | B21: 103 | C21: Haryana | D21: Hisar | E21: CHC | F21: CHC SORKHI | G21: =VLOOKUP(F21,Hospitals!E:H,4,FALSE) -> 28.99308 , 77.01507 | H21: 45532 | I21: 45532 | J21: 91.72 | K21: 88.166 | L21: 84.659 | M21: 52.941 | N21: 39.13 | O21: 39.13 | P21: 52.941 | Q21: 39.13 | R21: 39.13 | S21: 10 | T21: 8.333 | U21: 0 | V21: =AVERAGE(J21,M21,P21,S21) -> 51.9005 | W21: =AVERAGE(K21,N21,Q21,T21) -> 43.68975 | X21: =AVERAGE(L21,O21,R21,U21) -> 40.72975 | Y21: 13 | Z21: 007
A22: 963 | B22: 104 | C22: Haryana | D22: Hisar | E22: CHC | F22: CHC SISWAL | G22: =VLOOKUP(F22,Hospitals!E:H,4,FALSE) -> 29.14919 , 75.72165 | H22: 45561 | I22: 45561 | J22: 42.675 | K22: 39.645 | L22: 38.068 | M22: 29.412 | N22: 21.739 | O22: 21.739 | P22: 29.412 | Q22: 21.739 | R22: 21.739 | S22: 0 | T22: 0 | U22: 0 | V22: =AVERAGE(J22,M22,P22,S22) -> 25.37475 | W22: =AVERAGE(K22,N22,Q22,T22) -> 20.78075 | X22: =AVERAGE(L22,O22,R22,U22) -> 20.3865 | Y22: 13 | Z22: 007
A23: 836 | B23: 105 | C23: Haryana | D23: Hisar | E23: CHC | F23: CHC KHANDA KHERI | G23: =VLOOKUP(F23,Hospitals!E:H,4,FALSE) -> 28.61629 , 77.28988 | H23: 45748 | I23: 45748 | J23: 35.032 | K23: 32.544 | L23: 31.25 | M23: 58.824 | N23: 47.826 | O23: 47.826 | P23: 58.824 | Q23: 47.826 | R23: 47.826 | S23: 10 | T23: 8.333 | U23: 0 | V23: =AVERAGE(J23,M23,P23,S23) -> 40.67 | W23: =AVERAGE(K23,N23,Q23,T23) -> 34.13225 | X23: =AVERAGE(L23,O23,R23,U23) -> 31.7255 | Y23: 13 | Z23: 007
A24: 886 | B24: 106 | C24: Haryana | D24: Hisar | E24: CHC | F24: CHC SISAI BOLA | G24: =VLOOKUP(F24,Hospitals!E:H,4,FALSE) -> 29.17274 , 76.01374 | H24: 45483 | I24: 45483 | J24: 41.401 | K24: 40.828 | L24: 39.773 | M24: 11.765 | N24: 17.391 | O24: 17.391 | P24: 11.765 | Q24: 17.391 | R24: 17.391 | S24: 0 | T24: 0 | U24: 0 | V24: =AVERAGE(J24,M24,P24,S24) -> 16.23275 | W24: =AVERAGE(K24,N24,Q24,T24) -> 18.9025 | X24: =AVERAGE(L24,O24,R24,U24) -> 18.63875 | Y24: 13 | Z24: 007
A25: 1039 | B25: 107 | C25: Haryana | D25: Hisar | E25: CHC | F25: CHC UKLANA | G25: =VLOOKUP(F25,Hospitals!E:H,4,FALSE) -> 29.49838 , 75.87805 | H25: 45638 | I25: 45638 | J25: 34.395 | K25: 32.544 | L25: 31.25 | M25: 23.529 | N25: 17.391 | O25: 17.391 | P25: 23.529 | Q25: 17.391 | R25: 17.391 | S25: 10 | T25: 8.333 | U25: 0 | V25: =AVERAGE(J25,M25,P25,S25) -> 22.86325 | W25: =AVERAGE(K25,N25,Q25,T25) -> 18.91475 | X25: =AVERAGE(L25,O25,R25,U25) -> 16.508 | Y25: 13 | Z25: 007
A26: 962 | B26: 108 | C26: Haryana | D26: Hisar | E26: CHC | F26: CHC MIRCHPUR | G26: =VLOOKUP(F26,Hospitals!E:H,4,FALSE) -> 26.37886 , 79.40286 | H26: 45554 | I26: 45554 | J26: 35.032 | K26: 32.544 | L26: 31.25 | M26: 35.294 | N26: 26.087 | O26: 26.087 | P26: 35.294 | Q26: 26.087 | R26: 26.087 | S26: 10 | T26: 8.333 | U26: 0 | V26: =AVERAGE(J26,M26,P26,S26) -> 28.905 | W26: =AVERAGE(K26,N26,Q26,T26) -> 23.26275 | X26: =AVERAGE(L26,O26,R26,U26) -> 20.856 | Y26: 13 | Z26: 007
A27: 972 | B27: 109 | C27: Haryana | D27: Hisar | E27: CHC | F27: CHC ARYANAGAR | G27: =VLOOKUP(F27,Hospitals!E:H,4,FALSE) -> 29.11015 , 75.81853 | H27: 45553 | I27: 45553 | J27: 54.14 | K27: 50.888 | L27: 48.864 | M27: 35.294 | N27: 26.087 | O27: 26.087 | P27: 35.294 | Q27: 26.087 | R27: 26.087 | S27: 10 | T27: 8.333 | U27: 0 | V27: =AVERAGE(J27,M27,P27,S27) -> 33.682 | W27: =AVERAGE(K27,N27,Q27,T27) -> 27.84875 | X27: =AVERAGE(L27,O27,R27,U27) -> 25.2595 | Y27: 13 | Z27: 007
A28: 904 | B28: 11 | C28: Haryana | D28: Ambala | E28: PHC | F28: PHC MAJARI | G28: =VLOOKUP(F28,Hospitals!E:H,4,FALSE) -> 30.26829 , 76.77664 | H28: 45491 | I28: 45491 | J28: 35.032 | K28: 32.544 | L28: 31.25 | M28: 35.294 | N28: 26.087 | O28: 26.087 | P28: 35.294 | Q28: 26.087 | R28: 26.087 | S28: 0 | T28: 0 | U28: 0 | V28: =AVERAGE(J28,M28,P28,S28) -> 26.405 | W28: =AVERAGE(K28,N28,Q28,T28) -> 21.1795 | X28: =AVERAGE(L28,O28,R28,U28) -> 20.856 | Y28: 13 | Z28: 001
A29: 653 | B29: 110 | C29: Haryana | D29: Hisar | E29: DCH | F29: DISTRICT CIVIL HOSPITAL Hisar | G29: =VLOOKUP(F29,Hospitals!E:H,4,FALSE) -> 29.14386 , 75.72357 | H29: 45466 | I29: 45466 | J29: 100 | K29: 99.408 | L29: 99.432 | M29: 94.118 | N29: 86.957 | O29: 86.957 | P29: 94.118 | Q29: 86.957 | R29: 86.957 | S29: 40 | T29: 33.333 | U29: 14.286 | V29: =AVERAGE(J29,M29,P29,S29) -> 82.059 | W29: =AVERAGE(K29,N29,Q29,T29) -> 76.66375 | X29: =AVERAGE(L29,O29,R29,U29) -> 71.908 | Y29: 13 | Z29: 007
A30: 1254 | B30: 1101 | C30: Haryana | D30: Palwal | E30: DCH | F30: civil hospital palwal | G30: =VLOOKUP(F30,Hospitals!E:H,4,FALSE) -> 28.1354 , 77.3271 | H30: 45996 | I30: 45996 | J30: 40.127 | K30: 39.053 | L30: 38.068 | M30: 70.588 | N30: 69.565 | O30: 69.565 | P30: 70.588 | Q30: 69.565 | R30: 69.565 | S30: 30 | T30: 25 | U30: 0 | V30: =AVERAGE(J30,M30,P30,S30) -> 52.82575 | W30: =AVERAGE(K30,N30,Q30,T30) -> 50.79575 | X30: =AVERAGE(L30,O30,R30,U30) -> 44.2995 | Y30: 13 | Z30: 015
A31: 969 | B31: 111 | C31: Haryana | D31: Hisar | E31: PHC | F31: PHC LANDHRI | G31: =VLOOKUP(F31,Hospitals!E:H,4,FALSE) -> 29.38634 , 76.95565 | H31: 45524 | I31: 45524 | J31: 54.14 | K31: 50.888 | L31: 48.864 | M31: 47.059 | N31: 34.783 | O31: 34.783 | P31: 47.059 | Q31: 34.783 | R31: 34.783 | S31: 0 | T31: 0 | U31: 0 | V31: =AVERAGE(J31,M31,P31,S31) -> 37.0645 | W31: =AVERAGE(K31,N31,Q31,T31) -> 30.1135 | X31: =AVERAGE(L31,O31,R31,U31) -> 29.6075 | Y31: 13 | Z31: 007
A32: 858 | B32: 112 | C32: Haryana | D32: Hisar | E32: CHC | F32: CHC Mangali | G32: =VLOOKUP(F32,Hospitals!E:H,4,FALSE) -> 28.03182 , 76.1088 | H32: 45474 | I32: 45474 | J32: 51.592 | K32: 48.521 | L32: 46.591 | M32: 29.412 | N32: 21.739 | O32: 21.739 | P32: 29.412 | Q32: 21.739 | R32: 21.739 | S32: 20 | T32: 8.333 | U32: 0 | V32: =AVERAGE(J32,M32,P32,S32) -> 32.604 | W32: =AVERAGE(K32,N32,Q32,T32) -> 25.083 | X32: =AVERAGE(L32,O32,R32,U32) -> 22.51725 | Y32: 13 | Z32: 007
A33: 968 | B33: 113 | C33: Haryana | D33: Hisar | E33: PHC | F33: PHC KAIMARI | G33: =VLOOKUP(F33,Hospitals!E:H,4,FALSE) -> 29.04954 , 75.57425 | H33: 45524 | I33: - | J33: 45.223 | K33: 42.604 | L33: 40.909 | M33: 58.824 | N33: 43.478 | O33: 43.478 | P33: 58.824 | Q33: 43.478 | R33: 43.478 | S33: 0 | T33: 0 | U33: 0 | V33: =AVERAGE(J33,M33,P33,S33) -> 40.71775 | W33: =AVERAGE(K33,N33,Q33,T33) -> 32.39 | X33: =AVERAGE(L33,O33,R33,U33) -> 31.96625 | Y33: 13 | Z33: 007
A34: 887 | B34: 113 | C34: Haryana | D34: Hisar | E34: PHC | F34: PHC KAIMARI | G34: =VLOOKUP(F34,Hospitals!E:H,4,FALSE) -> 29.04954 , 75.57425 | H34: 45478 | I34: 45478 | J34: 45.223 | K34: 42.604 | L34: 40.909 | M34: 58.824 | N34: 43.478 | O34: 43.478 | P34: 58.824 | Q34: 43.478 | R34: 43.478 | S34: 0 | T34: 0 | U34: 0 | V34: =AVERAGE(J34,M34,P34,S34) -> 40.71775 | W34: =AVERAGE(K34,N34,Q34,T34) -> 32.39 | X34: =AVERAGE(L34,O34,R34,U34) -> 31.96625 | Y34: 13 | Z34: 007
A35: 884 | B35: 114 | C35: Haryana | D35: Hisar | E35: PHC | F35: PHC LADWA | G35: =VLOOKUP(F35,Hospitals!E:H,4,FALSE) -> 29.14919 , 75.72165 | H35: 45478 | I35: 45478 | J35: 24.841 | K35: 23.077 | L35: 22.159 | M35: 5.882 | N35: 4.348 | O35: 4.348 | P35: 5.882 | Q35: 4.348 | R35: 4.348 | S35: 0 | T35: 0 | U35: 0 | V35: =AVERAGE(J35,M35,P35,S35) -> 9.15125 | W35: =AVERAGE(K35,N35,Q35,T35) -> 7.94325 | X35: =AVERAGE(L35,O35,R35,U35) -> 7.71375 | Y35: 13 | Z35: 007
A36: 831 | B36: 115 | C36: Haryana | D36: Hisar | E36: PHC | F36: PHC NALWA | G36: =VLOOKUP(F36,Hospitals!E:H,4,FALSE) -> 29.39095 , 76.9635 | H36: 45477 | I36: 45477 | J36: 59.236 | K36: 55.621 | L36: 53.409 | M36: 52.941 | N36: 39.13 | O36: 39.13 | P36: 52.941 | Q36: 39.13 | R36: 39.13 | S36: 0 | T36: 0 | U36: 0 | V36: =AVERAGE(J36,M36,P36,S36) -> 41.2795 | W36: =AVERAGE(K36,N36,Q36,T36) -> 33.47025 | X36: =AVERAGE(L36,O36,R36,U36) -> 32.91725 | Y36: 13 | Z36: 007
A37: 871 | B37: 116 | C37: Haryana | D37: Hisar | E37: PHC | F37: PHC TALWANDI RUKKA | G37: =VLOOKUP(F37,Hospitals!E:H,4,FALSE) -> 29.13581 , 75.71701 | H37: 45475 | I37: 45475 | J37: 13.376 | K37: 12.426 | L37: 11.932 | M37: 17.647 | N37: 13.043 | O37: 13.043 | P37: 17.647 | Q37: 13.043 | R37: 13.043 | S37: 0 | T37: 0 | U37: 0 | V37: =AVERAGE(J37,M37,P37,S37) -> 12.1675 | W37: =AVERAGE(K37,N37,Q37,T37) -> 9.628 | X37: =AVERAGE(L37,O37,R37,U37) -> 9.5045 | Y37: 13 | Z37: 007
A38: 1030 | B38: 117 | C38: Haryana | D38: Hisar | E38: PHC | F38: PHC CHOUDHARYWAS | G38: =VLOOKUP(F38,Hospitals!E:H,4,FALSE) -> 29.43055 , 74.92088 | H38: 45605 | I38: 45605 | J38: 67.516 | K38: 63.314 | L38: 60.795 | M38: 23.529 | N38: 17.391 | O38: 17.391 | P38: 23.529 | Q38: 17.391 | R38: 17.391 | S38: 0 | T38: 0 | U38: 0 | V38: =AVERAGE(J38,M38,P38,S38) -> 28.6435 | W38: =AVERAGE(K38,N38,Q38,T38) -> 24.524 | X38: =AVERAGE(L38,O38,R38,U38) -> 23.89425 | Y38: 13 | Z38: 007
A39: 1063 | B39: 118 | C39: Haryana | D39: Hisar | E39: PHC | F39: PHC SATROAD KALAN | G39: =VLOOKUP(F39,Hospitals!E:H,4,FALSE) -> 29.39095 , 76.9635 | H39: 45559 | I39: 45775 | J39: 17.834 | K39: 16.568 | L39: 15.909 | M39: 0 | N39: 0 | O39: 0 | P39: 0 | Q39: 0 | R39: 0 | S39: 0 | T39: 0 | U39: 0 | V39: =AVERAGE(J39,M39,P39,S39) -> 4.4585 | W39: =AVERAGE(K39,N39,Q39,T39) -> 4.142 | X39: =AVERAGE(L39,O39,R39,U39) -> 3.97725 | Y39: 13 | Z39: 007
A40: 1061 | B40: 118 | C40: Haryana | D40: Hisar | E40: PHC | F40: PHC SATROAD KALAN | G40: =VLOOKUP(F40,Hospitals!E:H,4,FALSE) -> 29.39095 , 76.9635 | H40: 45556 | I40: 45559 | J40: 17.834 | K40: 16.568 | L40: 15.909 | M40: 0 | N40: 0 | O40: 0 | P40: 0 | Q40: 0 | R40: 0 | S40: 0 | T40: 0 | U40: 0 | V40: =AVERAGE(J40,M40,P40,S40) -> 4.4585 | W40: =AVERAGE(K40,N40,Q40,T40) -> 4.142 | X40: =AVERAGE(L40,O40,R40,U40) -> 3.97725 | Y40: 13 | Z40: 007
...

Sheet Hospitals
A1: Hospital ID | B1: Record ID | C1: State | D1: District | E1: Hospital Name | F1: Pincode | G1: Hospital Type | H1: GPS Location | I1: e_primary | J1: e_secondary | K1: e_tertiary | L1: i_primary | M1: i_secondary | N1: i_tertiary | O1: b_primary | P1: b_secondary | Q1: b_tertiary | R1: s_primary | S1: s_secondary | T1: s_tertiary
A2: 737 | B2: 690 | C2: Haryana | D2: Kaithal | E2: KIRTI HOSPITAL | F2: 136027 | G2: PRIVATE | H2: 29.77552 , 76.41003 | I2: {=VLOOKUP(E2,TPL!A:Z,9,FLASE)} -> #NAME?
A3: 101 | B3: 631 | C3: Haryana | D3: Gurugram | E3: Manipal Hospital, Gurugram | F3: 122017 | G3: PRIVATE | H3: 28.50358 , 77.04492
A4: 499 | B4: 390 | C4: Haryana | D4: Panipat | E4: MALIK HOSPITAL | F4: 132103 | G4: PRIVATE | H4: 30.70398 , 76.90092
A5: 195 | B5: 381 | C5: Haryana | D5: Yamuna Nagar | E5: PHC BHAMBHOL | F5: 133103 | G5: PHC | H5: 30.10148 , 77.275
A6: 352 | B6: 296 | C6: Haryana | D6: Kurukshetra | E6: CHC BARNA | F6: 136119 | G6: CHC | H6: 29.93261 , 76.7221
A7: 549 | B7: 809 | C7: Haryana | D7: Sirsa | E7: PHC PANNIWALA MOTTA | F7: 125077 | G7: PHC | H7: 29.70283 , 74.90854
A8: 5 | B8: 747 | C8: Haryana | D8: Ambala | E8: CHC AMBLI | F8: 134203 | G8: CHC | H8: 30.28297 , 76.71056
A9: 180 | B9: 385 | C9: Haryana | D9: Yamuna Nagar | E9: CHC NAHARPUR | F9: 135001 | G9: CHC | H9: 30.28297 , 76.71056
A10: 377 | B10: 318 | C10: Haryana | D10: Kurukshetra | E10: BS HEART CARE AND MULTISPECIALITY HOSPITAL | F10: 136118 | G10: PRIVATE | H10: 29.96938 , 76.86055
A11: 590 | B11: 625 | C11: Haryana | D11: Yamuna Nagar | E11: SHARMA HOSPITAL | F11: 135003 | G11: PRIVATE | H11: 30.15311 , 77.31937
A12: 187 | B12: 414 | C12: Haryana | D12: Yamuna Nagar | E12: PHC ALAHAR | F12: 135133 | G12: PHC | H12: 30.03427 , 77.20822
A13: 421 | B13: 585 | C13: Haryana | D13: Nuh | E13: PHC MARORA | F13: 122104 | G13: PHC | H13: 27.80045 , 76.95256
A14: 958 | B14: 965 | C14: Haryana | D14: Bhiwani | E14: PHC ALAKHPURA | F14: 127041 | G14: PHC | H14: 28.90345 , 76.57194
... A19: 560 | B19: 498 | C19: Haryana | D19: Sirsa | E19: PHC KALUANA | F19: 125103 | G19: PHC | H19: 28.99308 , 77.01507
A20: 80 | B20: 628 | C20: Haryana | D20: Gurugram | E20: KAMLA HOSPITAL | G20: PRIVATE | H20: 28.44633 , 76.9916
A21: 211 | B21: 826 | C21: Haryana | D21: Jhajjar | E21: PHC BAHU JHOLARI | F21: 124142 | G21: PHC | H21: 28.45705 , 76.32998
A22: 366 | B22: 301 | C22: Haryana | D22: Kurukshetra | E22: PHC GUDHA | F22: 136132 | G22: PHC | H22: 29.99809 , 77.03342
A23: 498 | B23: 371 | C23: Haryana | D23: Panipat | E23: AYUSHMAN BHAV HEALTH INSTITUTE | F23: 132103 | G23: PRIVATE | H23: 29.31916 , 76.99052
A24: 178 | B24: 393 | C24: Haryana | D24: Yamuna Nagar | E24: CHC SADHAURA | F24: 133204 | G24: CHC | H24: 30.39232 , 76.79836
A25: 45 | B25: 1163 | C25: Haryana | D25: Bhiwani | E25: SHARMA HOSPITAL | G25: PRIVATE | H25: 28.80094 , 76.14127
A26: 292 | B26: 1128 | C26: Haryana | D26: Karnal | E26: PHC BARSAT | F26: 132114 | G26: PHC | H26: 29.53052 , 76.98514
A27: 315 | B27: 324 | C27: Haryana | D27: Karnal | E27: SUSHIL GARG HOSPITAL | F27: 132001 | G27: PRIVATE | H27: 29.68781 , 76.99825
A28: 550 | B28: 796 | C28: Haryana | D28: Sirsa | E28: PHC BANI | F28: 125075 | G28: PHC | H28: 29.43055 , 74.92088
A29: 493 | B29: 369 | C29: Haryana | D29: Panipat | E29: PAHUJA HOSPITAL | F29: 132103 | G29: PRIVATE | H29: 29.4038 , 76.97085
A30: 694 | B30: 437 | C30: Haryana | D30: Faridabad | E30: PHC PANHERA KHURD | F30: 121004 | G30: PHC | H30: 28.26443 , 77.39979
A31: 571 | B31: 421 | C31: Haryana | D31: Sirsa | E31: CIVIL HOSPITAL CHAUTALA | F31: 125101 | G31: SDH | H31: 29.78566 , 74.5293
A32: 546 | B32: 419 | C32: Haryana | D32: Sirsa | E32: CHC KALANWALI | F32: 125201 | G32: CHC | H32: 29.54455 , 75.06314
A33: 719 | B33: 442 | C33: Haryana | D33: Kaithal | E33: PHC BALU | G33: PHC | H33: 29.81876 , 76.39904
A34: 459 | B34: 406 | C34: Haryana | D34: Panipat | E34: CHC DADLANA | F34: 132140 | G34: CHC | H34: 29.49163 , 76.86056
A35: 356 | B35: 1035 | C35: Haryana | D35: Kurukshetra | E35: CHC MATHANA | F35: 136131 | G35: CHC | H35: 29.77552 , 76.41003
A36: 814 | B36: 661 | C36: Haryana | D36: Sirsa | E36: POONIA HOSPITAL | F36: 125055 | G36: PRIVATE | H36: 30.90096 , 75.85728
A37: 358 | B37: 791 | C37: Haryana | D37: Kurukshetra | E37: PHC AMIN | F37: 136038 | G37: PHC | H37: 29.31151 , 76.88363
A38: 559 | B38: 478 | C38: Haryana | D38: Sirsa | E38: PHC JOTTANWALI | F38: 125104 | G38: PHC | H38: 30.90096 , 75.85728
A39: 1000 | B39: 1118 | C39: Haryana | D39: Fatehabad | E39: KHANNA ENT AND DENTAL HOSPITAL | F39: 125120 | G39: PRIVATE | H39: 29.70815 , 75.90863
A40: 884 | B40: 929 | C40: Haryana | D40: Sirsa | E40: HOLY NURSING HOME | F40: 125055 | G40: PRIVATE | H40: 29.54461 , 75.02606
A41: 693 | B41: 448 | C41: Haryana | D41: Faridabad | E41: PHC MOHNA | F41: 121004 | G41: PHC | H41: 28.2772 , 77.32094
A42: 191 | B42: 387 | C42: Haryana | D42: Yamuna Nagar | E42: PHC SABAPUR | F42: 135101 | G42: PHC | H42: 30.2403 , 77.1363
A43: 176 | B43: 315 | C43: Haryana | D43: Yamuna Nagar | E43: CHC CHHACHHAULI | F43: 135103 | G43: CHC | H43: 30.37759 , 76.86056
A44: 608 | B44: 438 | C44: Haryana | D44: Yamuna Nagar | E44: PARAS HOSPITAL | F44: 135001 | G44: PRIVATE | H44: 30.14911 , 77.3058
...
